Workbook

Sheet 點餐明細資料
A1: 台味豐閣餐飲 — 客戶點餐明細資料庫
A2: 資料期間：2026年9月1日 ~ 2026年10月10日 ｜ 記錄總數：320 筆 ｜ 幣別：新台幣 (TWD)
A4: 項次 | B4: 訂單編號 | C4: 訂餐日期 | D4: 客戶編號 | E4: 客戶名稱 | F4: 菜品分類 | G4: 菜品代號 | H4: 菜品名稱 | I4: 所點份數 | J4: 菜品單價 | K4: 小計金額
A5: 1 | B5: ORD-20260008 | C5: 2026-09-01 | D5: CUST-1049 | E5: 蕭雅涵 | F5: 肉品 | G5: MEA-04 | H5: 醬燒蔥爆牛肉 | I5: 4 | J5: 230 | K5: =I5*J5
A6: 2 | B6: ORD-20260074 | C6: 2026-09-01 | D6: CUST-1025 | E6: 葉宜君 | F6: 海鮮 | G6: SEA-02 | H6: 豆酥鱈魚 | I6: 5 | J6: 240 | K6: =I6*J6
A7: 3 | B7: ORD-20260088 | C7: 2026-09-01 | D7: CUST-1030 | E7: 呂建德 | F7: 主食 | G7: STA-05 | H7: 招牌古早味滷肉飯(大) | I7: 1 | J7: 80 | K7: =I7*J7
A8: 4 | B8: ORD-20260004 | C8: 2026-09-02 | D8: CUST-1006 | E8: 王俊傑 | F8: 肉品 | G8: MEA-07 | H8: 薑絲炒大腸 | I8: 1 | J8: 210 | K8: =I8*J8
A9: 5 | B9: ORD-20260055 | C9: 2026-09-02 | D9: CUST-1038 | E9: 鼎盛工程顧問 | F9: 主食 | G9: STA-01 | H9: 台式古早味炒米粉 | I9: 1 | J9: 120 | K9: =I9*J9
A10: 6 | B10: ORD-20260120 | C10: 2026-09-02 | D10: CUST-1008 | E10: 劉冠宇 | F10: 海鮮 | G10: SEA-02 | H10: 豆酥鱈魚 | I10: 1 | J10: 240 | K10: =I10*J10
A11: 7 | B11: ORD-20260167 | C11: 2026-09-02 | D11: CUST-1026 | E11: 何孟勳 | F11: 主食 | G11: STA-03 | H11: 櫻花蝦炒飯 | I11: 1 | J11: 150 | K11: =I11*J11
A12: 8 | B12: ORD-20260173 | C12: 2026-09-02 | D12: CUST-1048 | E12: 顏立威 | F12: 湯品 | G12: SOU-06 | H12: 貢丸蘿蔔排骨湯 | I12: 1 | J12: 120 | K12: =I12*J12
A13: 9 | B13: ORD-20260241 | C13: 2026-09-02 | D13: CUST-1006 | E13: 王俊傑 | F13: 肉品 | G13: MEA-08 | H13: 麻油松阪豬 | I13: 1 | J13: 250 | K13: =I13*J13
A14: 10 | B14: ORD-20260257 | C14: 2026-09-02 | D14: CUST-1041 | E14: 彭思涵 | F14: 主食 | G14: STA-04 | H14: 烏魚子炒飯 | I14: 1 | J14: 220 | K14: =I14*J14
A15: 11 | B15: ORD-20260287 | C15: 2026-09-02 | D15: CUST-1003 | E15: 張淑芬 | F15: 海鮮 | G15: SEA-06 | H15: 清蒸金目鱸魚片 | I15: 1 | J15: 240 | K15: =I15*J15
A16: 12 | B16: ORD-20260319 | C16: 2026-09-02 | D16: CUST-1040 | E16: 微星多媒體室 | F16: 主食 | G16: STA-01 | H16: 台式古早味炒米粉 | I16: 2 | J16: 120 | K16: =I16*J16
... A324: 320 | B324: ORD-20260320 | C324: 2026-10-10 | D324: CUST-1015 | E324: 郭宏達 | F324: 飲品 | G324: DRK-01 | H324: 古早味冬瓜檸檬 | I324: 1 | J324: 80 | K324: =I324*J324
A325: 合計 (Total) | I325: =SUM(I5:I324) | J325: =AVERAGE(J5:J324) | K325: =SUM(K5:K324)

Sheet 菜品主檔目錄
A1: 台式菜品目錄與價格主檔
A2: 收錄台式料理 7 大分類、44 款經典熱銷菜色 ｜ 單價範圍：$80 ~ $250
A4: 菜品代號 | B4: 菜品名稱 | C4: 菜品分類 | D4: 標準單價 (NT$) | E4: 點餐累積筆數 | F4: 累計銷售總額
A5: APP-01 | B5: 台式蒜泥白肉 | C5: 冷盤 | D5: 160 | E5: =COUNTIF(點餐明細資料!G5:G324, A5) | F5: =SUMIF(點餐明細資料!G5:G324, A5, 點餐明細資料!K5:K324)
A6: APP-02 | B6: 五味透抽 | C6: 冷盤 | D6: 220 | E6: =COUNTIF(點餐明細資料!G5:G324, A6) | F6: =SUMIF(點餐明細資料!G5:G324, A6, 點餐明細資料!K5:K324)
A7: APP-03 | B7: 紹興醉雞卷 | C7: 冷盤 | D7: 210 | E7: =COUNTIF(點餐明細資料!G5:G324, A7) | F7: =SUMIF(點餐明細資料!G5:G324, A7, 點餐明細資料!K5:K324)
A8: APP-04 | B8: 台式涼拌小黃瓜 | C8: 冷盤 | D8: 80 | E8: =COUNTIF(點餐明細資料!G5:G324, A8) | F8: =SUMIF(點餐明細資料!G5:G324, A8, 點餐明細資料!K5:K324)
A9: APP-05 | B9: 黃金皮蛋豆腐 | C9: 冷盤 | D9: 90 | E9: =COUNTIF(點餐明細資料!G5:G324, A9) | F9: =SUMIF(點餐明細資料!G5:G324, A9, 點餐明細資料!K5:K324)
A10: APP-06 | B10: 涼拌海蜇皮 | C10: 冷盤 | D10: 180 | E10: =COUNTIF(點餐明細資料!G5:G324, A10) | F10: =SUMIF(點餐明細資料!G5:G324, A10, 點餐明細資料!K5:K324)
A11: APP-07 | B11: 煙燻粉肝 | C11: 冷盤 | D11: 120 | E11: =COUNTIF(點餐明細資料!G5:G324, A11) | F11: =SUMIF(點餐明細資料!G5:G324, A11, 點餐明細資料!K5:K324)
A12: MEA-01 | B12: 經典台式三杯雞 | C12: 肉品 | D12: 240 | E12: =COUNTIF(點餐明細資料!G5:G324, A12) | F12: =SUMIF(點餐明細資料!G5:G324, A12, 點餐明細資料!K5:K324)
A13: MEA-02 | B13: 阿嬤紅燒肉 | C13: 肉品 | D13: 220 | E13: =COUNTIF(點餐明細資料!G5:G324, A13) | F13: =SUMIF(點餐明細資料!G5:G324, A13, 點餐明細資料!K5:K324)
A14: MEA-03 | B14: 客家小炒 | C14: 肉品 | D14: 190 | E14: =COUNTIF(點餐明細資料!G5:G324, A14) | F14: =SUMIF(點餐明細資料!G5:G324, A14, 點餐明細資料!K5:K324)
A15: MEA-04 | B15: 醬燒蔥爆牛肉 | C15: 肉品 | D15: 230 | E15: =COUNTIF(點餐明細資料!G5:G324, A15) | F15: =SUMIF(點餐明細資料!G5:G324, A15, 點餐明細資料!K5:K324)
A16: MEA-05 | B16: 糖醋里肌肉 | C16: 肉品 | D16: 200 | E16: =COUNTIF(點餐明細資料!G5:G324, A16) | F16: =SUMIF(點餐明細資料!G5:G324, A16, 點餐明細資料!K5:K324)
A17: MEA-06 | B17: 香酥炸排骨 | C17: 肉品 | D17: 160 | E17: =COUNTIF(點餐明細資料!G5:G324, A17) | F17: =SUMIF(點餐明細資料!G5:G324, A17, 點餐明細資料!K5:K324)
A18: MEA-07 | B18: 薑絲炒大腸 | C18: 肉品 | D18: 210 | E18: =COUNTIF(點餐明細資料!G5:G324, A18) | F18: =SUMIF(點餐明細資料!G5:G324, A18, 點餐明細資料!K5:K324)
A19: MEA-08 | B19: 麻油松阪豬 | C19: 肉品 | D19: 250 | E19: =COUNTIF(點餐明細資料!G5:G324, A19) | F19: =SUMIF(點餐明細資料!G5:G324, A19, 點餐明細資料!K5:K324)
A20: SEA-01 | B20: 鳳梨蝦球 | C20: 海鮮 | D20: 250 | E20: =COUNTIF(點餐明細資料!G5:G324, A20) | F20: =SUMIF(點餐明細資料!G5:G324, A20, 點餐明細資料!K5:K324)
A21: SEA-02 | B21: 豆酥鱈魚 | C21: 海鮮 | D21: 240 | E21: =COUNTIF(點餐明細資料!G5:G324, A21) | F21: =SUMIF(點餐明細資料!G5:G324, A21, 點餐明細資料!K5:K324)
A22: SEA-03 | B22: 塔香炒蛤蜊 | C22: 海鮮 | D22: 190 | E22: =COUNTIF(點餐明細資料!G5:G324, A22) | F22: =SUMIF(點餐明細資料!G5:G324, A22, 點餐明細資料!K5:K324)
A23: SEA-04 | B23: 金沙中卷 | C23: 海鮮 | D23: 230 | E23: =COUNTIF(點餐明細資料!G5:G324, A23) | F23: =SUMIF(點餐明細資料!G5:G324, A23, 點餐明細資料!K5:K324)
A24: SEA-05 | B24: 乾煎虱目魚肚 | C24: 海鮮 | D24: 180 | E24: =COUNTIF(點餐明細資料!G5:G324, A24) | F24: =SUMIF(點餐明細資料!G5:G324, A24, 點餐明細資料!K5:K324)
A25: SEA-06 | B25: 清蒸金目鱸魚片 | C25: 海鮮 | D25: 240 | E25: =COUNTIF(點餐明細資料!G5:G324, A25) | F25: =SUMIF(點餐明細資料!G5:G324, A25, 點餐明細資料!K5:K324)
A26: SEA-07 | B26: 生炒花枝 | C26: 海鮮 | D26: 200 | E26: =COUNTIF(點餐明細資料!G5:G324, A26) | F26: =SUMIF(點餐明細資料!G5:G324, A26, 點餐明細資料!K5:K324)
A27: VEG-01 | B27: 清炒高麗菜 | C27: 蔬菜 | D27: 110 | E27: =COUNTIF(點餐明細資料!G5:G324, A27) | F27: =SUMIF(點餐明細資料!G5:G324, A27, 點餐明細資料!K5:K324)
A28: VEG-02 | B28: 櫻花蝦炒高麗菜 | C28: 蔬菜 | D28: 150 | E28: =COUNTIF(點餐明細資料!G5:G324, A28) | F28: =SUMIF(點餐明細資料!G5:G324, A28, 點餐明細資料!K5:K324)
A29: VEG-03 | B29: 樹子炒水蓮 | C29: 蔬菜 | D29: 140 | E29: =COUNTIF(點餐明細資料!G5:G324, A29) | F29: =SUMIF(點餐明細資料!G5:G324, A29, 點餐明細資料!K5:K324)
A30: VEG-04 | B30: 蒜炒地瓜葉 | C30: 蔬菜 | D30: 90 | E30: =COUNTIF(點餐明細資料!G5:G324, A30) | F30: =SUMIF(點餐明細資料!G5:G324, A30, 點餐明細資料!K5:K324)
A31: VEG-05 | B31: 鹹蛋苦瓜 | C31: 蔬菜 | D31: 160 | E31: =COUNTIF(點餐明細資料!G5:G324, A31) | F31: =SUMIF(點餐明細資料!G5:G324, A31, 點餐明細資料!K5:K324)
A32: VEG-06 | B32: 吻仔魚莧菜 | C32: 蔬菜 | D32: 140 | E32: =COUNTIF(點餐明細資料!G5:G324, A32) | F32: =SUMIF(點餐明細資料!G5:G324, A32, 點餐明細資料!K5:K324)
A33: VEG-07 | B33: 開陽白菜滷 | C33: 蔬菜 | D33: 130 | E33: =COUNTIF(點餐明細資料!G5:G324, A33) | F33: =SUMIF(點餐明細資料!G5:G324, A33, 點餐明細資料!K5:K324)
A34: SOU-01 | B34: 剝皮辣椒雞湯 | C34: 湯品 | D34: 220 | E34: =COUNTIF(點餐明細資料!G5:G324, A34) | F34: =SUMIF(點餐明細資料!G5:G324, A34, 點餐明細資料!K5:K324)
A35: SOU-02 | B35: 鳳梨苦瓜雞湯 | C35: 湯品 | D35: 210 | E35: =COUNTIF(點餐明細資料!G5:G324, A35) | F35: =SUMIF(點餐明細資料!G5:G324, A35, 點餐明細資料!K5:K324)
A36: SOU-03 | B36: 鮮魚味噌豆腐湯 | C36: 湯品 | D36: 160 | E36: =COUNTIF(點餐明細資料!G5:G324, A36) | F36: =SUMIF(點餐明細資料!G5:G324, A36, 點餐明細資料!K5:K324)
A37: SOU-04 | B37: 薑絲蛤蜊湯 | C37: 湯品 | D37: 130 | E37: =COUNTIF(點餐明細資料!G5:G324, A37) | F37: =SUMIF(點餐明細資料!G5:G324, A37, 點餐明細資料!K5:K324)
A38: SOU-05 | B38: 古早味西魯肉湯 | C38: 湯品 | D38: 190 | E38: =COUNTIF(點餐明細資料!G5:G324, A38) | F38: =SUMIF(點餐明細資料!G5:G324, A38, 點餐明細資料!K5:K324)
A39: SOU-06 | B39: 貢丸蘿蔔排骨湯 | C39: 湯品 | D39: 120 | E39: =COUNTIF(點餐明細資料!G5:G324, A39) | F39: =SUMIF(點餐明細資料!G5:G324, A39, 點餐明細資料!K5:K324)
A40: STA-01 | B40: 台式古早味炒米粉 | C40: 主食 | D40: 120 | E40: =COUNTIF(點餐明細資料!G5:G324, A40) | F40: =SUMIF(點餐明細資料!G5:G324, A40, 點餐明細資料!K5:K324)
A41: STA-02 | B41: 台式肉絲炒麵 | C41: 主食 | D41: 110 | E41: =COUNTIF(點餐明細資料!G5:G324, A41) | F41: =SUMIF(點餐明細資料!G5:G324, A41, 點餐明細資料!K5:K324)
...
